#VRML_SIM R2023b utf8

EXTERNPROTO "https://raw.githubusercontent.com/cyberbotics/webots/R2023b/projects/objects/backgrounds/protos/TexturedBackground.proto"
EXTERNPROTO "https://raw.githubusercontent.com/cyberbotics/webots/R2023b/projects/objects/backgrounds/protos/TexturedBackgroundLight.proto"
EXTERNPROTO "https://raw.githubusercontent.com/cyberbotics/webots/R2023b/projects/objects/floors/protos/RectangleArena.proto"
EXTERNPROTO "https://raw.githubusercontent.com/cyberbotics/webots/R2023b/projects/objects/factory/conveyors/protos/ConveyorBelt.proto"

WorldInfo {
  contactProperties [
    ContactProperties {
      material1 "InteriorWheelMat"
      coulombFriction [
        0, 2, 0
      ]
      frictionRotation -0.785398 0
      bounce 0
      forceDependentSlip [
        10, 0
      ]
    }
  ]
}
Viewpoint {
  orientation -0.5773502691896258 0.5773502691896258 0.5773502691896258 2.0944
  position 9.967877640690377e-18 2.9618836418051407e-16 1.6417400696059563
}
TexturedBackground {
}
TexturedBackgroundLight {
}
RectangleArena {
  floorSize 3 3
}


DEF celluvoyer Robot {
  children [
        DEF cell_0_0 Pose {
    translation 0.087 -0.0 0.101 
    children [
      Solid {
          children [
            Group {
              children [
                DEF cell_0_0_dist_0 DistanceSensor {
              translation 0 0 0.1 
              rotation 0 1 0 -1.5708003061004252 
              name "cell_0_0_dist_0"
              lookupTable [
                0.012 0 0 
                0.1 1 0 
              ]
            }
                CadShape {
                  url [
                    "../assets/Celluvoyer_0_1.dae"
                  ]
                }
              ]
            }
            DEF V1 Pose {
              translation 0.04 0 0.085
              rotation 0 0 1 1.5707996938995747
              children [
                HingeJoint {
                  jointParameters HingeJointParameters {
                    axis 0 1 0
                  }
                  device [
                    RotationalMotor {
                      name "cell_0_0_m1"
                    }
                  ]
                  endPoint Solid {
                    rotation -1 2.7476575974040475e-15 4.710270166978368e-16 1.5707993877991355
                    children [
                      Group {
                        children [
                          DEF wheel_shape Shape {
                            appearance PBRAppearance {
                              transparency 1
                            }
                            geometry Cylinder {
                              height 0.025
                              radius 0.027
                            }
                          }
                          CadShape {
                            url [
                              "../assets/Celluvoyer_wheel_0_1.dae"
                            ]
                          }
                        ]
                      }
                    ]
                    name "cell_0_0_wheel_1"
                    contactMaterial "InteriorWheelMat"
                    boundingObject USE wheel_shape
                    physics Physics {
                    }
                  }
                }
              ]
            }
            DEF V2 Pose {
              translation -0.02 0.034 0.085
              rotation 0 0 1 -2.6179953071795863
              children [
                HingeJoint {
                  jointParameters HingeJointParameters {
                    axis 0 1 0
                  }
                  device [
                    RotationalMotor {
                      name "cell_0_0_m2"
                    }
                  ]
                  endPoint Solid {
                    rotation -1 -8.635471348454006e-16 -7.850510172479671e-16 1.5707993877991429
                    children [
                      Group {
                        children [
                          DEF wheel_shape Shape {
                            appearance PBRAppearance {
                              transparency 1
                            }
                            geometry Cylinder {
                              height 0.025
                              radius 0.027
                            }
                          }
                          CadShape {
                            url [
                              "../assets/Celluvoyer_wheel_0_1.dae"
                            ]
                          }
                        ]
                      }
                    ]
                    name "cell_0_0_wheel_2"
                    contactMaterial "InteriorWheelMat"
                    boundingObject USE wheel_shape
                    physics Physics {
                    }
                  }
                }
              ]
            }
            DEF V3 Pose {
              translation -0.02 -0.034 0.085
              rotation 0 0 1 -0.523595307179586
              children [
                HingeJoint {
                  jointParameters HingeJointParameters {
                    axis 0 1 0
                  }
                  device [
                    RotationalMotor {
                      name "cell_0_0_m3"
                    }
                  ]
                  endPoint Solid {
                    rotation -1 1.5700900556594532e-16 8.635495306126993e-16 1.5707993877991393
                    children [
                      Group {
                        children [
                          DEF wheel_shape Shape {
                            appearance PBRAppearance {
                              transparency 1
                            }
                            geometry Cylinder {
                              height 0.025
                              radius 0.027
                            }
                          }
                          CadShape {
                            url [
                              "../assets/Celluvoyer_wheel_0_1.dae"
                            ]
                          }
                        ]
                      }
                    ]
                    name "cell_0_0_wheel_3"
                    contactMaterial "InteriorWheelMat"
                    boundingObject USE wheel_shape
                    physics Physics {
                    }
                  }
                }
              ]
            }
            DEF hexagon_shape Shape {
              appearance PBRAppearance {
                baseColor 1 0.333333 1
                transparency 1
              }
              geometry Cylinder {
                bottom FALSE
                height 0.2
                radius 0.09
                top FALSE
                subdivision 6
              }
            }
          ]
          name "cell_0_0_body"
          boundingObject USE hexagon_shape
          physics Physics {
          }
        }
    ]
    }DEF cell_1_0 Pose {
    translation 0.0 -0.152 0.101 
    children [
      Solid {
          children [
            Group {
              children [
                DEF cell_1_0_dist_0 DistanceSensor {
              translation 0 0 0.1 
              rotation 0 1 0 -1.5708003061004252 
              name "cell_1_0_dist_0"
              lookupTable [
                0.012 0 0 
                0.1 1 0 
              ]
            }
                CadShape {
                  url [
                    "../assets/Celluvoyer_0_1.dae"
                  ]
                }
              ]
            }
            DEF V1 Pose {
              translation 0.04 0 0.085
              rotation 0 0 1 1.5707996938995747
              children [
                HingeJoint {
                  jointParameters HingeJointParameters {
                    axis 0 1 0
                  }
                  device [
                    RotationalMotor {
                      name "cell_1_0_m1"
                    }
                  ]
                  endPoint Solid {
                    rotation -1 2.7476575974040475e-15 4.710270166978368e-16 1.5707993877991355
                    children [
                      Group {
                        children [
                          DEF wheel_shape Shape {
                            appearance PBRAppearance {
                              transparency 1
                            }
                            geometry Cylinder {
                              height 0.025
                              radius 0.027
                            }
                          }
                          CadShape {
                            url [
                              "../assets/Celluvoyer_wheel_0_1.dae"
                            ]
                          }
                        ]
                      }
                    ]
                    name "cell_1_0_wheel_1"
                    contactMaterial "InteriorWheelMat"
                    boundingObject USE wheel_shape
                    physics Physics {
                    }
                  }
                }
              ]
            }
            DEF V2 Pose {
              translation -0.02 0.034 0.085
              rotation 0 0 1 -2.6179953071795863
              children [
                HingeJoint {
                  jointParameters HingeJointParameters {
                    axis 0 1 0
                  }
                  device [
                    RotationalMotor {
                      name "cell_1_0_m2"
                    }
                  ]
                  endPoint Solid {
                    rotation -1 -8.635471348454006e-16 -7.850510172479671e-16 1.5707993877991429
                    children [
                      Group {
                        children [
                          DEF wheel_shape Shape {
                            appearance PBRAppearance {
                              transparency 1
                            }
                            geometry Cylinder {
                              height 0.025
                              radius 0.027
                            }
                          }
                          CadShape {
                            url [
                              "../assets/Celluvoyer_wheel_0_1.dae"
                            ]
                          }
                        ]
                      }
                    ]
                    name "cell_1_0_wheel_2"
                    contactMaterial "InteriorWheelMat"
                    boundingObject USE wheel_shape
                    physics Physics {
                    }
                  }
                }
              ]
            }
            DEF V3 Pose {
              translation -0.02 -0.034 0.085
              rotation 0 0 1 -0.523595307179586
              children [
                HingeJoint {
                  jointParameters HingeJointParameters {
                    axis 0 1 0
                  }
                  device [
                    RotationalMotor {
                      name "cell_1_0_m3"
                    }
                  ]
                  endPoint Solid {
                    rotation -1 1.5700900556594532e-16 8.635495306126993e-16 1.5707993877991393
                    children [
                      Group {
                        children [
                          DEF wheel_shape Shape {
                            appearance PBRAppearance {
                              transparency 1
                            }
                            geometry Cylinder {
                              height 0.025
                              radius 0.027
                            }
                          }
                          CadShape {
                            url [
                              "../assets/Celluvoyer_wheel_0_1.dae"
                            ]
                          }
                        ]
                      }
                    ]
                    name "cell_1_0_wheel_3"
                    contactMaterial "InteriorWheelMat"
                    boundingObject USE wheel_shape
                    physics Physics {
                    }
                  }
                }
              ]
            }
            DEF hexagon_shape Shape {
              appearance PBRAppearance {
                baseColor 1 0.333333 1
                transparency 1
              }
              geometry Cylinder {
                bottom FALSE
                height 0.2
                radius 0.09
                top FALSE
                subdivision 6
              }
            }
          ]
          name "cell_1_0_body"
          boundingObject USE hexagon_shape
          physics Physics {
          }
        }
    ]
    }DEF cell_2_0 Pose {
    translation 0.087 -0.304 0.101 
    children [
      Solid {
          children [
            Group {
              children [
                DEF cell_2_0_dist_0 DistanceSensor {
              translation 0 0 0.1 
              rotation 0 1 0 -1.5708003061004252 
              name "cell_2_0_dist_0"
              lookupTable [
                0.012 0 0 
                0.1 1 0 
              ]
            }
                CadShape {
                  url [
                    "../assets/Celluvoyer_0_1.dae"
                  ]
                }
              ]
            }
            DEF V1 Pose {
              translation 0.04 0 0.085
              rotation 0 0 1 1.5707996938995747
              children [
                HingeJoint {
                  jointParameters HingeJointParameters {
                    axis 0 1 0
                  }
                  device [
                    RotationalMotor {
                      name "cell_2_0_m1"
                    }
                  ]
                  endPoint Solid {
                    rotation -1 2.7476575974040475e-15 4.710270166978368e-16 1.5707993877991355
                    children [
                      Group {
                        children [
                          DEF wheel_shape Shape {
                            appearance PBRAppearance {
                              transparency 1
                            }
                            geometry Cylinder {
                              height 0.025
                              radius 0.027
                            }
                          }
                          CadShape {
                            url [
                              "../assets/Celluvoyer_wheel_0_1.dae"
                            ]
                          }
                        ]
                      }
                    ]
                    name "cell_2_0_wheel_1"
                    contactMaterial "InteriorWheelMat"
                    boundingObject USE wheel_shape
                    physics Physics {
                    }
                  }
                }
              ]
            }
            DEF V2 Pose {
              translation -0.02 0.034 0.085
              rotation 0 0 1 -2.6179953071795863
              children [
                HingeJoint {
                  jointParameters HingeJointParameters {
                    axis 0 1 0
                  }
                  device [
                    RotationalMotor {
                      name "cell_2_0_m2"
                    }
                  ]
                  endPoint Solid {
                    rotation -1 -8.635471348454006e-16 -7.850510172479671e-16 1.5707993877991429
                    children [
                      Group {
                        children [
                          DEF wheel_shape Shape {
                            appearance PBRAppearance {
                              transparency 1
                            }
                            geometry Cylinder {
                              height 0.025
                              radius 0.027
                            }
                          }
                          CadShape {
                            url [
                              "../assets/Celluvoyer_wheel_0_1.dae"
                            ]
                          }
                        ]
                      }
                    ]
                    name "cell_2_0_wheel_2"
                    contactMaterial "InteriorWheelMat"
                    boundingObject USE wheel_shape
                    physics Physics {
                    }
                  }
                }
              ]
            }
            DEF V3 Pose {
              translation -0.02 -0.034 0.085
              rotation 0 0 1 -0.523595307179586
              children [
                HingeJoint {
                  jointParameters HingeJointParameters {
                    axis 0 1 0
                  }
                  device [
                    RotationalMotor {
                      name "cell_2_0_m3"
                    }
                  ]
                  endPoint Solid {
                    rotation -1 1.5700900556594532e-16 8.635495306126993e-16 1.5707993877991393
                    children [
                      Group {
                        children [
                          DEF wheel_shape Shape {
                            appearance PBRAppearance {
                              transparency 1
                            }
                            geometry Cylinder {
                              height 0.025
                              radius 0.027
                            }
                          }
                          CadShape {
                            url [
                              "../assets/Celluvoyer_wheel_0_1.dae"
                            ]
                          }
                        ]
                      }
                    ]
                    name "cell_2_0_wheel_3"
                    contactMaterial "InteriorWheelMat"
                    boundingObject USE wheel_shape
                    physics Physics {
                    }
                  }
                }
              ]
            }
            DEF hexagon_shape Shape {
              appearance PBRAppearance {
                baseColor 1 0.333333 1
                transparency 1
              }
              geometry Cylinder {
                bottom FALSE
                height 0.2
                radius 0.09
                top FALSE
                subdivision 6
              }
            }
          ]
          name "cell_2_0_body"
          boundingObject USE hexagon_shape
          physics Physics {
          }
        }
    ]
    }DEF cell_3_0 Pose {
    translation 0.0 -0.45599999999999996 0.101 
    children [
      Solid {
          children [
            Group {
              children [
                DEF cell_3_0_dist_0 DistanceSensor {
              translation 0 0 0.1 
              rotation 0 1 0 -1.5708003061004252 
              name "cell_3_0_dist_0"
              lookupTable [
                0.012 0 0 
                0.1 1 0 
              ]
            }
                CadShape {
                  url [
                    "../assets/Celluvoyer_0_1.dae"
                  ]
                }
              ]
            }
            DEF V1 Pose {
              translation 0.04 0 0.085
              rotation 0 0 1 1.5707996938995747
              children [
                HingeJoint {
                  jointParameters HingeJointParameters {
                    axis 0 1 0
                  }
                  device [
                    RotationalMotor {
                      name "cell_3_0_m1"
                    }
                  ]
                  endPoint Solid {
                    rotation -1 2.7476575974040475e-15 4.710270166978368e-16 1.5707993877991355
                    children [
                      Group {
                        children [
                          DEF wheel_shape Shape {
                            appearance PBRAppearance {
                              transparency 1
                            }
                            geometry Cylinder {
                              height 0.025
                              radius 0.027
                            }
                          }
                          CadShape {
                            url [
                              "../assets/Celluvoyer_wheel_0_1.dae"
                            ]
                          }
                        ]
                      }
                    ]
                    name "cell_3_0_wheel_1"
                    contactMaterial "InteriorWheelMat"
                    boundingObject USE wheel_shape
                    physics Physics {
                    }
                  }
                }
              ]
            }
            DEF V2 Pose {
              translation -0.02 0.034 0.085
              rotation 0 0 1 -2.6179953071795863
              children [
                HingeJoint {
                  jointParameters HingeJointParameters {
                    axis 0 1 0
                  }
                  device [
                    RotationalMotor {
                      name "cell_3_0_m2"
                    }
                  ]
                  endPoint Solid {
                    rotation -1 -8.635471348454006e-16 -7.850510172479671e-16 1.5707993877991429
                    children [
                      Group {
                        children [
                          DEF wheel_shape Shape {
                            appearance PBRAppearance {
                              transparency 1
                            }
                            geometry Cylinder {
                              height 0.025
                              radius 0.027
                            }
                          }
                          CadShape {
                            url [
                              "../assets/Celluvoyer_wheel_0_1.dae"
                            ]
                          }
                        ]
                      }
                    ]
                    name "cell_3_0_wheel_2"
                    contactMaterial "InteriorWheelMat"
                    boundingObject USE wheel_shape
                    physics Physics {
                    }
                  }
                }
              ]
            }
            DEF V3 Pose {
              translation -0.02 -0.034 0.085
              rotation 0 0 1 -0.523595307179586
              children [
                HingeJoint {
                  jointParameters HingeJointParameters {
                    axis 0 1 0
                  }
                  device [
                    RotationalMotor {
                      name "cell_3_0_m3"
                    }
                  ]
                  endPoint Solid {
                    rotation -1 1.5700900556594532e-16 8.635495306126993e-16 1.5707993877991393
                    children [
                      Group {
                        children [
                          DEF wheel_shape Shape {
                            appearance PBRAppearance {
                              transparency 1
                            }
                            geometry Cylinder {
                              height 0.025
                              radius 0.027
                            }
                          }
                          CadShape {
                            url [
                              "../assets/Celluvoyer_wheel_0_1.dae"
                            ]
                          }
                        ]
                      }
                    ]
                    name "cell_3_0_wheel_3"
                    contactMaterial "InteriorWheelMat"
                    boundingObject USE wheel_shape
                    physics Physics {
                    }
                  }
                }
              ]
            }
            DEF hexagon_shape Shape {
              appearance PBRAppearance {
                baseColor 1 0.333333 1
                transparency 1
              }
              geometry Cylinder {
                bottom FALSE
                height 0.2
                radius 0.09
                top FALSE
                subdivision 6
              }
            }
          ]
          name "cell_3_0_body"
          boundingObject USE hexagon_shape
          physics Physics {
          }
        }
    ]
    }DEF cell_4_0 Pose {
    translation 0.087 -0.608 0.101 
    children [
      Solid {
          children [
            Group {
              children [
                DEF cell_4_0_dist_0 DistanceSensor {
              translation 0 0 0.1 
              rotation 0 1 0 -1.5708003061004252 
              name "cell_4_0_dist_0"
              lookupTable [
                0.012 0 0 
                0.1 1 0 
              ]
            }
                CadShape {
                  url [
                    "../assets/Celluvoyer_0_1.dae"
                  ]
                }
              ]
            }
            DEF V1 Pose {
              translation 0.04 0 0.085
              rotation 0 0 1 1.5707996938995747
              children [
                HingeJoint {
                  jointParameters HingeJointParameters {
                    axis 0 1 0
                  }
                  device [
                    RotationalMotor {
                      name "cell_4_0_m1"
                    }
                  ]
                  endPoint Solid {
                    rotation -1 2.7476575974040475e-15 4.710270166978368e-16 1.5707993877991355
                    children [
                      Group {
                        children [
                          DEF wheel_shape Shape {
                            appearance PBRAppearance {
                              transparency 1
                            }
                            geometry Cylinder {
                              height 0.025
                              radius 0.027
                            }
                          }
                          CadShape {
                            url [
                              "../assets/Celluvoyer_wheel_0_1.dae"
                            ]
                          }
                        ]
                      }
                    ]
                    name "cell_4_0_wheel_1"
                    contactMaterial "InteriorWheelMat"
                    boundingObject USE wheel_shape
                    physics Physics {
                    }
                  }
                }
              ]
            }
            DEF V2 Pose {
              translation -0.02 0.034 0.085
              rotation 0 0 1 -2.6179953071795863
              children [
                HingeJoint {
                  jointParameters HingeJointParameters {
                    axis 0 1 0
                  }
                  device [
                    RotationalMotor {
                      name "cell_4_0_m2"
                    }
                  ]
                  endPoint Solid {
                    rotation -1 -8.635471348454006e-16 -7.850510172479671e-16 1.5707993877991429
                    children [
                      Group {
                        children [
                          DEF wheel_shape Shape {
                            appearance PBRAppearance {
                              transparency 1
                            }
                            geometry Cylinder {
                              height 0.025
                              radius 0.027
                            }
                          }
                          CadShape {
                            url [
                              "../assets/Celluvoyer_wheel_0_1.dae"
                            ]
                          }
                        ]
                      }
                    ]
                    name "cell_4_0_wheel_2"
                    contactMaterial "InteriorWheelMat"
                    boundingObject USE wheel_shape
                    physics Physics {
                    }
                  }
                }
              ]
            }
            DEF V3 Pose {
              translation -0.02 -0.034 0.085
              rotation 0 0 1 -0.523595307179586
              children [
                HingeJoint {
                  jointParameters HingeJointParameters {
                    axis 0 1 0
                  }
                  device [
                    RotationalMotor {
                      name "cell_4_0_m3"
                    }
                  ]
                  endPoint Solid {
                    rotation -1 1.5700900556594532e-16 8.635495306126993e-16 1.5707993877991393
                    children [
                      Group {
                        children [
                          DEF wheel_shape Shape {
                            appearance PBRAppearance {
                              transparency 1
                            }
                            geometry Cylinder {
                              height 0.025
                              radius 0.027
                            }
                          }
                          CadShape {
                            url [
                              "../assets/Celluvoyer_wheel_0_1.dae"
                            ]
                          }
                        ]
                      }
                    ]
                    name "cell_4_0_wheel_3"
                    contactMaterial "InteriorWheelMat"
                    boundingObject USE wheel_shape
                    physics Physics {
                    }
                  }
                }
              ]
            }
            DEF hexagon_shape Shape {
              appearance PBRAppearance {
                baseColor 1 0.333333 1
                transparency 1
              }
              geometry Cylinder {
                bottom FALSE
                height 0.2
                radius 0.09
                top FALSE
                subdivision 6
              }
            }
          ]
          name "cell_4_0_body"
          boundingObject USE hexagon_shape
          physics Physics {
          }
        }
    ]
    }
  ]
  name "main_robot"
  physics Physics {
  }
  locked TRUE
  controller "<extern>"
  synchronization FALSE
}
 

Robot {
  name "Supervisor"
  controller "<extern>"
  supervisor TRUE
}

