#VRML_SIM R2023b utf8
PROTO celluvoyer_0_2 [
  field SFVec3f translation 0 0 0.1 
field SFRotation rotation 0 0 1 0 
unconnectedField SFVec2f lines_columns_size 2 2 
field SFString controller "controller"
field MFString wheel_graphic "C:/Users/toupa/Desktop/ESE - S1/PFE/3D/New folder/worlds/Celluvoyer_wheel_0_1.dae" 
field MFString chasis_graphic "C:/Users/toupa/Desktop/ESE - S1/PFE/3D/New folder/worlds/Celluvoyer_0_1.dae" 

]
{
  DEF cell_0_0 Robot {
      translation 0 0 0.1 
      rotation 0 0 1 0 
      children [
        DEF V1 Pose {
          translation 0.04 0 0.1
          rotation 0 0 1 1.5707996938995747
          children [
            HingeJoint {
              jointParameters HingeJointParameters {
                axis 0 1 0
              }
              device [
                DEF m1 RotationalMotor {
                  name "m1"
                }
              ]
              endPoint Solid {
                rotation -1 1.334576547310534e-15 -7.850450278297259e-17 1.5707993877991409
                children [
                  Group {
                    children [
                      DEF wheel_shape Shape {
                        appearance PBRAppearance {
                          transparency 1
                        }
                        geometry Cylinder {
                          height 0.025
                          radius 0.027
                        }
                      }
                      CadShape {
                        url IS wheel_graphic
                      }
                    ]
                  }
                ]
                name "solid(1)"
                boundingObject USE wheel_shape
                physics Physics {
                }
              }
            }
          ]
        }
        DEF V2 Pose {
          translation -0.02 0.034 0.1
          rotation 0 0 1 -2.6179953071795863
          children [
            HingeJoint {
              jointParameters HingeJointParameters {
                axis 0 1 0
              }
              device [
                DEF m2 RotationalMotor {
                  name "m2"
                }
              ]
              endPoint Solid {
                rotation -1 -8.635495306126964e-16 -7.850450278297241e-16 1.5707993877991457
                children [
                  Group {
                    children [
                      DEF wheel_shape Shape {
                        appearance PBRAppearance {
                          transparency 1
                        }
                        geometry Cylinder {
                          height 0.025
                          radius 0.027
                        }
                      }
                      CadShape {
                        url IS wheel_graphic
                      }
                    ]
                  }
                ]
                name "solid(2)"
                boundingObject USE wheel_shape
                physics Physics {
                }
              }
            }
          ]
        }
        DEF V3 Pose {
          translation -0.02 -0.034 0.1
          rotation 0 0 1 -0.523595307179586
          children [
            HingeJoint {
              jointParameters HingeJointParameters {
                axis 0 1 0
              }
              device [
                DEF m3 RotationalMotor {
                  name "m3"
                }
              ]
              endPoint Solid {
                rotation -1 -3.925225139148627e-16 3.1401801113189015e-16 1.5707993877991426
                children [
                  Group {
                    children [
                      DEF wheel_shape Shape {
                        appearance PBRAppearance {
                          transparency 1
                        }
                        geometry Cylinder {
                          height 0.025
                          radius 0.027
                        }
                      }
                      CadShape {
                        url IS wheel_graphic
                      }
                    ]
                  }
                ]
                boundingObject USE wheel_shape
                physics Physics {
                }
              }
            }
          ]
        }
        Pose {
          children [
            CadShape {
              url IS chasis_graphic
            }
          ]
        }
        DEF hexagon_shape Shape {
          appearance PBRAppearance {
          }
          geometry Cylinder {
            height 0.2
            radius 0.09
            top FALSE
            bottom FALSE
            subdivision 6
          }
          castShadows TRUE
        }
      ]
      name "cell_0_0"
      boundingObject USE hexagon_shape
      physics Physics {
      }
      controller "None"
    }
DEF cell_0_0_152 Robot {
      translation 0 0.152 0.1 
      rotation 0 0 1 0 
      children [
        DEF V1 Pose {
          translation 0.04 0 0.1
          rotation 0 0 1 1.5707996938995747
          children [
            HingeJoint {
              jointParameters HingeJointParameters {
                axis 0 1 0
              }
              device [
                DEF m1 RotationalMotor {
                  name "m1"
                }
              ]
              endPoint Solid {
                rotation -1 1.334576547310534e-15 -7.850450278297259e-17 1.5707993877991409
                children [
                  Group {
                    children [
                      DEF wheel_shape Shape {
                        appearance PBRAppearance {
                          transparency 1
                        }
                        geometry Cylinder {
                          height 0.025
                          radius 0.027
                        }
                      }
                      CadShape {
                        url IS wheel_graphic
                      }
                    ]
                  }
                ]
                name "solid(1)"
                boundingObject USE wheel_shape
                physics Physics {
                }
              }
            }
          ]
        }
        DEF V2 Pose {
          translation -0.02 0.034 0.1
          rotation 0 0 1 -2.6179953071795863
          children [
            HingeJoint {
              jointParameters HingeJointParameters {
                axis 0 1 0
              }
              device [
                DEF m2 RotationalMotor {
                  name "m2"
                }
              ]
              endPoint Solid {
                rotation -1 -8.635495306126964e-16 -7.850450278297241e-16 1.5707993877991457
                children [
                  Group {
                    children [
                      DEF wheel_shape Shape {
                        appearance PBRAppearance {
                          transparency 1
                        }
                        geometry Cylinder {
                          height 0.025
                          radius 0.027
                        }
                      }
                      CadShape {
                        url IS wheel_graphic
                      }
                    ]
                  }
                ]
                name "solid(2)"
                boundingObject USE wheel_shape
                physics Physics {
                }
              }
            }
          ]
        }
        DEF V3 Pose {
          translation -0.02 -0.034 0.1
          rotation 0 0 1 -0.523595307179586
          children [
            HingeJoint {
              jointParameters HingeJointParameters {
                axis 0 1 0
              }
              device [
                DEF m3 RotationalMotor {
                  name "m3"
                }
              ]
              endPoint Solid {
                rotation -1 -3.925225139148627e-16 3.1401801113189015e-16 1.5707993877991426
                children [
                  Group {
                    children [
                      DEF wheel_shape Shape {
                        appearance PBRAppearance {
                          transparency 1
                        }
                        geometry Cylinder {
                          height 0.025
                          radius 0.027
                        }
                      }
                      CadShape {
                        url IS wheel_graphic
                      }
                    ]
                  }
                ]
                boundingObject USE wheel_shape
                physics Physics {
                }
              }
            }
          ]
        }
        Pose {
          children [
            CadShape {
              url IS chasis_graphic
            }
          ]
        }
        DEF hexagon_shape Shape {
          appearance PBRAppearance {
          }
          geometry Cylinder {
            height 0.2
            radius 0.09
            top FALSE
            bottom FALSE
            subdivision 6
          }
          castShadows TRUE
        }
      ]
      name "cell_0_0.152"
      boundingObject USE hexagon_shape
      physics Physics {
      }
      controller "None"
    }
DEF cell_0_0_304 Robot {
      translation 0 0.304 0.1 
      rotation 0 0 1 0 
      children [
        DEF V1 Pose {
          translation 0.04 0 0.1
          rotation 0 0 1 1.5707996938995747
          children [
            HingeJoint {
              jointParameters HingeJointParameters {
                axis 0 1 0
              }
              device [
                DEF m1 RotationalMotor {
                  name "m1"
                }
              ]
              endPoint Solid {
                rotation -1 1.334576547310534e-15 -7.850450278297259e-17 1.5707993877991409
                children [
                  Group {
                    children [
                      DEF wheel_shape Shape {
                        appearance PBRAppearance {
                          transparency 1
                        }
                        geometry Cylinder {
                          height 0.025
                          radius 0.027
                        }
                      }
                      CadShape {
                        url IS wheel_graphic
                      }
                    ]
                  }
                ]
                name "solid(1)"
                boundingObject USE wheel_shape
                physics Physics {
                }
              }
            }
          ]
        }
        DEF V2 Pose {
          translation -0.02 0.034 0.1
          rotation 0 0 1 -2.6179953071795863
          children [
            HingeJoint {
              jointParameters HingeJointParameters {
                axis 0 1 0
              }
              device [
                DEF m2 RotationalMotor {
                  name "m2"
                }
              ]
              endPoint Solid {
                rotation -1 -8.635495306126964e-16 -7.850450278297241e-16 1.5707993877991457
                children [
                  Group {
                    children [
                      DEF wheel_shape Shape {
                        appearance PBRAppearance {
                          transparency 1
                        }
                        geometry Cylinder {
                          height 0.025
                          radius 0.027
                        }
                      }
                      CadShape {
                        url IS wheel_graphic
                      }
                    ]
                  }
                ]
                name "solid(2)"
                boundingObject USE wheel_shape
                physics Physics {
                }
              }
            }
          ]
        }
        DEF V3 Pose {
          translation -0.02 -0.034 0.1
          rotation 0 0 1 -0.523595307179586
          children [
            HingeJoint {
              jointParameters HingeJointParameters {
                axis 0 1 0
              }
              device [
                DEF m3 RotationalMotor {
                  name "m3"
                }
              ]
              endPoint Solid {
                rotation -1 -3.925225139148627e-16 3.1401801113189015e-16 1.5707993877991426
                children [
                  Group {
                    children [
                      DEF wheel_shape Shape {
                        appearance PBRAppearance {
                          transparency 1
                        }
                        geometry Cylinder {
                          height 0.025
                          radius 0.027
                        }
                      }
                      CadShape {
                        url IS wheel_graphic
                      }
                    ]
                  }
                ]
                boundingObject USE wheel_shape
                physics Physics {
                }
              }
            }
          ]
        }
        Pose {
          children [
            CadShape {
              url IS chasis_graphic
            }
          ]
        }
        DEF hexagon_shape Shape {
          appearance PBRAppearance {
          }
          geometry Cylinder {
            height 0.2
            radius 0.09
            top FALSE
            bottom FALSE
            subdivision 6
          }
          castShadows TRUE
        }
      ]
      name "cell_0_0.304"
      boundingObject USE hexagon_shape
      physics Physics {
      }
      controller "None"
    }
DEF cell_0_087_0_38 Robot {
      translation 0.087 0.38 0.1 
      rotation 0 0 1 0 
      children [
        DEF V1 Pose {
          translation 0.04 0 0.1
          rotation 0 0 1 1.5707996938995747
          children [
            HingeJoint {
              jointParameters HingeJointParameters {
                axis 0 1 0
              }
              device [
                DEF m1 RotationalMotor {
                  name "m1"
                }
              ]
              endPoint Solid {
                rotation -1 1.334576547310534e-15 -7.850450278297259e-17 1.5707993877991409
                children [
                  Group {
                    children [
                      DEF wheel_shape Shape {
                        appearance PBRAppearance {
                          transparency 1
                        }
                        geometry Cylinder {
                          height 0.025
                          radius 0.027
                        }
                      }
                      CadShape {
                        url IS wheel_graphic
                      }
                    ]
                  }
                ]
                name "solid(1)"
                boundingObject USE wheel_shape
                physics Physics {
                }
              }
            }
          ]
        }
        DEF V2 Pose {
          translation -0.02 0.034 0.1
          rotation 0 0 1 -2.6179953071795863
          children [
            HingeJoint {
              jointParameters HingeJointParameters {
                axis 0 1 0
              }
              device [
                DEF m2 RotationalMotor {
                  name "m2"
                }
              ]
              endPoint Solid {
                rotation -1 -8.635495306126964e-16 -7.850450278297241e-16 1.5707993877991457
                children [
                  Group {
                    children [
                      DEF wheel_shape Shape {
                        appearance PBRAppearance {
                          transparency 1
                        }
                        geometry Cylinder {
                          height 0.025
                          radius 0.027
                        }
                      }
                      CadShape {
                        url IS wheel_graphic
                      }
                    ]
                  }
                ]
                name "solid(2)"
                boundingObject USE wheel_shape
                physics Physics {
                }
              }
            }
          ]
        }
        DEF V3 Pose {
          translation -0.02 -0.034 0.1
          rotation 0 0 1 -0.523595307179586
          children [
            HingeJoint {
              jointParameters HingeJointParameters {
                axis 0 1 0
              }
              device [
                DEF m3 RotationalMotor {
                  name "m3"
                }
              ]
              endPoint Solid {
                rotation -1 -3.925225139148627e-16 3.1401801113189015e-16 1.5707993877991426
                children [
                  Group {
                    children [
                      DEF wheel_shape Shape {
                        appearance PBRAppearance {
                          transparency 1
                        }
                        geometry Cylinder {
                          height 0.025
                          radius 0.027
                        }
                      }
                      CadShape {
                        url IS wheel_graphic
                      }
                    ]
                  }
                ]
                boundingObject USE wheel_shape
                physics Physics {
                }
              }
            }
          ]
        }
        Pose {
          children [
            CadShape {
              url IS chasis_graphic
            }
          ]
        }
        DEF hexagon_shape Shape {
          appearance PBRAppearance {
          }
          geometry Cylinder {
            height 0.2
            radius 0.09
            top FALSE
            bottom FALSE
            subdivision 6
          }
          castShadows TRUE
        }
      ]
      name "cell_0.087_0.38"
      boundingObject USE hexagon_shape
      physics Physics {
      }
      controller "None"
    }
DEF cell_0_087_0_532 Robot {
      translation 0.087 0.532 0.1 
      rotation 0 0 1 0 
      children [
        DEF V1 Pose {
          translation 0.04 0 0.1
          rotation 0 0 1 1.5707996938995747
          children [
            HingeJoint {
              jointParameters HingeJointParameters {
                axis 0 1 0
              }
              device [
                DEF m1 RotationalMotor {
                  name "m1"
                }
              ]
              endPoint Solid {
                rotation -1 1.334576547310534e-15 -7.850450278297259e-17 1.5707993877991409
                children [
                  Group {
                    children [
                      DEF wheel_shape Shape {
                        appearance PBRAppearance {
                          transparency 1
                        }
                        geometry Cylinder {
                          height 0.025
                          radius 0.027
                        }
                      }
                      CadShape {
                        url IS wheel_graphic
                      }
                    ]
                  }
                ]
                name "solid(1)"
                boundingObject USE wheel_shape
                physics Physics {
                }
              }
            }
          ]
        }
        DEF V2 Pose {
          translation -0.02 0.034 0.1
          rotation 0 0 1 -2.6179953071795863
          children [
            HingeJoint {
              jointParameters HingeJointParameters {
                axis 0 1 0
              }
              device [
                DEF m2 RotationalMotor {
                  name "m2"
                }
              ]
              endPoint Solid {
                rotation -1 -8.635495306126964e-16 -7.850450278297241e-16 1.5707993877991457
                children [
                  Group {
                    children [
                      DEF wheel_shape Shape {
                        appearance PBRAppearance {
                          transparency 1
                        }
                        geometry Cylinder {
                          height 0.025
                          radius 0.027
                        }
                      }
                      CadShape {
                        url IS wheel_graphic
                      }
                    ]
                  }
                ]
                name "solid(2)"
                boundingObject USE wheel_shape
                physics Physics {
                }
              }
            }
          ]
        }
        DEF V3 Pose {
          translation -0.02 -0.034 0.1
          rotation 0 0 1 -0.523595307179586
          children [
            HingeJoint {
              jointParameters HingeJointParameters {
                axis 0 1 0
              }
              device [
                DEF m3 RotationalMotor {
                  name "m3"
                }
              ]
              endPoint Solid {
                rotation -1 -3.925225139148627e-16 3.1401801113189015e-16 1.5707993877991426
                children [
                  Group {
                    children [
                      DEF wheel_shape Shape {
                        appearance PBRAppearance {
                          transparency 1
                        }
                        geometry Cylinder {
                          height 0.025
                          radius 0.027
                        }
                      }
                      CadShape {
                        url IS wheel_graphic
                      }
                    ]
                  }
                ]
                boundingObject USE wheel_shape
                physics Physics {
                }
              }
            }
          ]
        }
        Pose {
          children [
            CadShape {
              url IS chasis_graphic
            }
          ]
        }
        DEF hexagon_shape Shape {
          appearance PBRAppearance {
          }
          geometry Cylinder {
            height 0.2
            radius 0.09
            top FALSE
            bottom FALSE
            subdivision 6
          }
          castShadows TRUE
        }
      ]
      name "cell_0.087_0.532"
      boundingObject USE hexagon_shape
      physics Physics {
      }
      controller "None"
    }
 
}